<?xml version="1.0" ?>
<sdf version="1.8">
    <world name="car_world">
        <physics name="1ms" type="ode">
            <max_step_size>0.001</max_step_size>
            <real_time_factor>1.0</real_time_factor>
        </physics>
        
        <!-- Add the sensors system plugin here -->
        <plugin
            filename="ignition-gazebo6-sensors-system"
            name="ignition::gazebo::systems::Sensors">
            <render_engine>ogre2</render_engine>
        </plugin>
        
        <plugin
            filename="ignition-gazebo6-physics-system"
            name="ignition::gazebo::systems::Physics">
        </plugin>
        <plugin
            filename="ignition-gazebo6-user-commands-system"
            name="ignition::gazebo::systems::UserCommands">
        </plugin>
        <plugin
            filename="ignition-gazebo6-scene-broadcaster-system"
            name="ignition::gazebo::systems::SceneBroadcaster">
        </plugin>
        <plugin
            filename="ignition-gazebo6-imu-system"
            name="ignition::gazebo::systems::Imu">
        </plugin>

        <light type="directional" name="sun">
            <cast_shadows>true</cast_shadows>
            <pose>0 0 10 0 0 0</pose>
            <diffuse>0.8 0.8 0.8 1</diffuse>
            <specular>0.2 0.2 0.2 1</specular>
            <attenuation>
                <range>1000</range>
                <constant>0.9</constant>
                <linear>0.01</linear>
                <quadratic>0.001</quadratic>
            </attenuation>
            <direction>-0.0 0.1 -0.9</direction>
        </light>

        <model name="ground_plane">
            <static>true</static>
            <link name="link">
                <collision name="collision">
                    <geometry>
                        <plane>
                            <normal>0 0 1</normal>
                            <size>100 100</size>
                        </plane>
                    </geometry>
                </collision>
                <visual name="visual">
                    <geometry>
                        <plane>
                            <normal>0 0 1</normal>
                            <size>100 100</size>
                        </plane>
                    </geometry>
                    <material>
                        <ambient>0.8 0.8 0.8 1</ambient>
                        <diffuse>0.8 0.8 0.8 1</diffuse>
                        <specular>0.8 0.8 0.8 1</specular>
                    </material>
                </visual>
            </link>
        </model>

        <!-- Fixed camera model -->
        <model name="top_view_camera">
            <static>true</static>
            <pose>0 0 8 0 1.5708 0</pose>
            <link name="camera_link">
                <sensor name="rgb_camera" type="camera">
                    <always_on>1</always_on>
                    <update_rate>30</update_rate>
                    <visualize>true</visualize>
                    <topic>/camera/image_raw</topic>
                    <camera>
                        <horizontal_fov>1.5708</horizontal_fov>
                        <image>
                            <width>640</width>
                            <height>480</height>
                            <format>R8G8B8</format>
                        </image>
                        <clip>
                            <near>0.1</near>
                            <far>15.0</far>
                        </clip>
                    </camera>
                </sensor>
            </link>
        </model>

        <!-- Enhanced target with bright red color -->
        <model name="target">
            <pose>3.5 2 0.2 0 0 0</pose>
            <link name="target_link">
                <collision name="collision">
                    <geometry>
                        <sphere>
                            <radius>0.2</radius>
                        </sphere>
                    </geometry>
                </collision>
                <visual name="visual">
                    <geometry>
                        <sphere>
                            <radius>0.2</radius>
                        </sphere>
                    </geometry>
                    <material>
                        <ambient>1 0 0 1</ambient>
                        <diffuse>1 0 0 1</diffuse>
                        <specular>1 0 0 1</specular>
                        <emissive>0.2 0 0 1</emissive>
                    </material>
                </visual>
            </link>
        </model>

        <!-- Labyrinth with distinct colors for better detection -->
        <model name="labyrinth">
            <static>true</static>
            <pose>0 0 0 0 0 0</pose>
            <link name="labyrinth_link">
                <collision name="wall1_collision">
                    <pose>-5 0 0.5 0 0 0</pose>
                    <geometry>
                        <box>
                            <size>0.2 10 1</size>
                        </box>
                    </geometry>
                </collision>
                <visual name="wall1_visual">
                    <pose>-5 0 0.5 0 0 0</pose>
                    <geometry>
                        <box>
                            <size>0.2 10 1</size>
                        </box>
                    </geometry>
                    <material>
                        <ambient>1 1 0 1</ambient>
                        <diffuse>1 1 0 1</diffuse>
                    </material>
                </visual>
                <collision name="wall2_collision">
                    <pose>5 0 0.5 0 0 0</pose>
                    <geometry>
                        <box>
                            <size>0.2 10 1</size>
                        </box>
                    </geometry>
                </collision>
                <visual name="wall2_visual">
                    <pose>5 0 0.5 0 0 0</pose>
                    <geometry>
                        <box>
                            <size>0.2 10 1</size>
                        </box>
                    </geometry>
                    <material>
                        <ambient>1 1 0 1</ambient>
                        <diffuse>1 1 0 1</diffuse>
                    </material>
                </visual>
                <collision name="wall3_collision">
                    <pose>0 5 0.5 0 0 1.5708</pose>
                    <geometry>
                        <box>
                            <size>0.2 10 1</size>
                        </box>
                    </geometry>
                </collision>
                <visual name="wall3_visual">
                    <pose>0 5 0.5 0 0 1.5708</pose>
                    <geometry>
                        <box>
                            <size>0.2 10 1</size>
                        </box>
                    </geometry>
                    <material>
                        <ambient>1 1 0 1</ambient>
                        <diffuse>1 1 0 1</diffuse>
                    </material>
                </visual>
                <collision name="wall4a_collision">
                    <pose>-2 -5 0.5 0 0 1.5708</pose>
                    <geometry>
                        <box>
                            <size>0.2 6 1</size>
                        </box>
                    </geometry>
                </collision>
                <visual name="wall4a_visual">
                    <pose>-2 -5 0.5 0 0 1.5708</pose>
                    <geometry>
                        <box>
                            <size>0.2 6 1</size>
                        </box>
                    </geometry>
                    <material>
                        <ambient>1 1 0 1</ambient>
                        <diffuse>1 1 0 1</diffuse>
                    </material>
                </visual>
                <collision name="wall4b_collision">
                    <pose>3 -5 0.5 0 0 1.5708</pose>
                    <geometry>
                        <box>
                            <size>0.2 4 1</size>
                        </box>
                    </geometry>
                </collision>
                <visual name="wall4b_visual">
                    <pose>3 -5 0.5 0 0 1.5708</pose>
                    <geometry>
                        <box>
                            <size>0.2 4 1</size>
                        </box>
                    </geometry>
                    <material>
                        <ambient>1 1 0 1</ambient>
                        <diffuse>1 1 0 1</diffuse>
                    </material>
                </visual>
                <collision name="wall5_collision">
                    <pose>2 0.5 0.5 0 0 0</pose>
                    <geometry>
                        <box>
                            <size>0.2 3 1</size>
                        </box>
                    </geometry>
                </collision>
                <visual name="wall5_visual">
                    <pose>2 0.5 0.5 0 0 0</pose>
                    <geometry>
                        <box>
                            <size>0.2 3 1</size>
                        </box>
                    </geometry>
                    <material>
                        <ambient>1 1 0 1</ambient>
                        <diffuse>1 1 0 1</diffuse>
                    </material>
                </visual>
                <collision name="wall6_collision">
                    <pose>1 2 0.5 0 0 1.5708</pose>
                    <geometry>
                        <box>
                            <size>0.2 2.5 1</size>
                        </box>
                    </geometry>
                </collision>
                <visual name="wall6_visual">
                    <pose>1 2 0.5 0 0 1.5708</pose>
                    <geometry>
                        <box>
                            <size>0.2 2.5 1</size>
                        </box>
                    </geometry>
                    <material>
                        <ambient>1 1 0 1</ambient>
                        <diffuse>1 1 0 1</diffuse>
                    </material>
                </visual>
            </link>
        </model>

        <!-- Your vehicle model (unchanged) -->
        <model name="vehicle_blue" canonical_link="chassis">
            <pose relative_to="world">0 0 0 0 0 0</pose>
            <link name="chassis">
                <pose relative_to="__model__">-1 -1 0.335 0 0 0</pose>
                <inertial>
                    <mass>1.14395</mass>
                    <inertia>
                        <ixx>0.095329</ixx>
                        <ixy>0</ixy>
                        <ixz>0</ixz>
                        <iyy>0.381317</iyy>
                        <iyz>0</iyz>
                        <izz>0.476646</izz>
                    </inertia>
                </inertial>
                <visual name="visual">
                    <pose>0.7 0.7 -0.26 1.5707 0 -1.5707</pose>
                    <geometry>
                        <mesh>
                            <uri>file:///home/aldon/ros2_ws/src/my_robot/MySDF/ROBOT.STL</uri>
                            <scale>0.01 0.01 0.01</scale>
                        </mesh>
                    </geometry>
                    <material>
                        <ambient>0.0 0.0 1.0 1</ambient>
                        <diffuse>0.0 0.0 1.0 1</diffuse>
                        <specular>0.0 0.0 1.0 1</specular>
                    </material>
                </visual>
                <collision name="collision">
                    <pose>0.7 0.7 -0.26 1.5707 0 -1.5707</pose>
                    <geometry>
                        <mesh>
                            <uri>file:///home/aldon/ros2_ws/src/my_robot/MySDF/ROBOT.STL</uri>
                            <scale>0.01 0.01 0.01</scale>
                        </mesh>
                    </geometry>
                </collision>
                <sensor name="imu_sensor" type="imu">
                    <always_on>true</always_on>
                    <update_rate>100</update_rate>
                    <topic>/imu</topic>
                    <visualize>true</visualize>
                </sensor>
            </link>
            <link name="left_wheel">
                <pose relative_to="chassis">-0.4 0.895 0 1.5707 0 0</pose>
                <inertial>
                    <mass>1</mass>
                    <inertia>
                        <ixx>0.043333</ixx>
                        <ixy>0</ixy>
                        <ixz>0</ixz>
                        <iyy>0.043333</iyy>
                        <iyz>0</iyz>
                        <izz>0.08</izz>
                    </inertia>
                </inertial>
                <visual name="visual">
                    <geometry>
                        <cylinder>
                            <radius>0.335</radius>
                            <length>0.25</length>
                        </cylinder>
                    </geometry>
                    <material>
                        <ambient>0.0 0.0 0.0 1.0</ambient>
                        <diffuse>0.0 0.0 0.0 1.0</diffuse>
                        <specular>0.0 0.0 0.0 1.0</specular>
                    </material>
                </visual>
                <collision name="collision">
                    <geometry>
                        <cylinder>
                            <radius>0.335</radius>
                            <length>0.25</length>
                        </cylinder>
                    </geometry>
                </collision>
            </link>
            <link name="right_wheel">
                <pose relative_to="chassis">-0.4 -0.895 0 1.5707 0 0</pose>
                <inertial>
                    <mass>1</mass>
                    <inertia>
                        <ixx>0.043333</ixx>
                        <ixy>0</ixy>
                        <ixz>0</ixz>
                        <iyy>0.043333</iyy>
                        <iyz>0</iyz>
                        <izz>0.08</izz>
                    </inertia>
                </inertial>
                <visual name="visual">
                    <geometry>
                        <cylinder>
                            <radius>0.335</radius>
                            <length>0.25</length>
                        </cylinder>
                    </geometry>
                    <material>
                        <ambient>0.0 0.0 0.0 1.0</ambient>
                        <diffuse>0.0 0.0 0.0 1.0</diffuse>
                        <specular>0.0 0.0 0.0 1.0</specular>
                    </material>
                </visual>
                <collision name="collision">
                    <geometry>
                        <cylinder>
                            <radius>0.335</radius>
                            <length>0.25</length>
                        </cylinder>
                    </geometry>
                </collision>
            </link>
            <frame name="caster_frame">
                <pose relative_to="chassis">0.6 0 -0.29 0 0 0</pose>
            </frame>
            <link name="caster">
                <pose relative_to="caster_frame">0 0 0 0 0 0</pose>
                <inertial>
                    <mass>1</mass>
                    <inertia>
                        <ixx>0.016</ixx>
                        <ixy>0</ixy>
                        <ixz>0</ixz>
                        <iyy>0.016</iyy>
                        <iyz>0</iyz>
                        <izz>0.016</izz>
                    </inertia>
                </inertial>
                <visual name="visual">
                    <geometry>
                        <sphere>
                            <radius>0.045</radius>
                        </sphere>
                    </geometry>
                    <material>
                        <ambient>0.0 1 0.0 1</ambient>
                        <diffuse>0.0 1 0.0 1</diffuse>
                        <specular>0.0 1 0.0 1</specular>
                    </material>
                </visual>
                <collision name="collision">
                    <geometry>
                        <sphere>
                            <radius>0.2</radius>
                        </sphere>
                    </geometry>
                </collision>
            </link>
            <joint name="left_wheel_joint" type="revolute">
                <pose relative_to="left_wheel">0 0 0 0 0 0</pose>
                <parent>chassis</parent>
                <child>left_wheel</child>
                <axis>
                    <xyz expressed_in="__model__">0 1 0</xyz>
                    <limit>
                        <lower>-1.79769e+308</lower>
                        <upper>1.79769e+308</upper>
                    </limit>
                </axis>
            </joint>
            <joint name="right_wheel_joint" type="revolute">
                <pose relative_to="right_wheel">0 0 0 0 0 0</pose>
                <parent>chassis</parent>
                <child>right_wheel</child>
                <axis>
                    <xyz expressed_in="__model__">0 1 0</xyz>
                    <limit>
                        <lower>-1.79769e+308</lower>
                        <upper>1.79769e+308</upper>
                    </limit>
                </axis>
            </joint>
            <joint name="caster_wheel" type="ball">
                <parent>chassis</parent>
                <child>caster</child>
            </joint>
            <plugin
                filename="ignition-gazebo6-diff-drive-system"
                name="ignition::gazebo::systems::DiffDrive">
                <left_joint>left_wheel_joint</left_joint>
                <right_joint>right_wheel_joint</right_joint>
                <wheel_separation>1.54</wheel_separation>
                <wheel_radius>0.35</wheel_radius>
                <odom_publish_frequency>1</odom_publish_frequency>
                <topic>/cmd_vel</topic>
            </plugin>
            <!-- Moving Backward -->
            <plugin
                filename="ignition-gazebo6-triggered-publisher-system"
                name="ignition::gazebo::systems::TriggeredPublisher">
                <input type="ignition.msgs.Int32" topic="/keyboard/keypress">
                    <match field="data">16777237</match>
                </input>
                <output type="ignition.msgs.Twist" topic="/cmd_vel">
                    linear: {x: -0.5}, angular: {z: 0.0}
                </output>
            </plugin>
            <!-- Moving Left -->
            <plugin
                filename="ignition-gazebo6-triggered-publisher-system"
                name="ignition::gazebo::systems::TriggeredPublisher">
                <input type="ignition.msgs.Int32" topic="/keyboard/keypress">
                    <match field="data">16777234</match>
                </input>
                <output type="ignition.msgs.Twist" topic="/cmd_vel">
                    linear: {x: 0.0}, angular: {z: 0.5}
                </output>
            </plugin>
            <!-- Moving Up -->
            <plugin
                filename="ignition-gazebo6-triggered-publisher-system"
                name="ignition::gazebo::systems::TriggeredPublisher">
                <input type="ignition.msgs.Int32" topic="/keyboard/keypress">
                    <match field="data">16777235</match>
                </input>
                <output type="ignition.msgs.Twist" topic="/cmd_vel">
                    linear: {x: 0.5}, angular: {z: 0.0}
                </output>
            </plugin>
            <!-- Moving Right -->
            <plugin
                filename="ignition-gazebo6-triggered-publisher-system"
                name="ignition::gazebo::systems::TriggeredPublisher">
                <input type="ignition.msgs.Int32" topic="/keyboard/keypress">
                    <match field="data">16777236</match>
                </input>
                <output type="ignition.msgs.Twist" topic="/cmd_vel">
                    linear: {x: 0.0}, angular: {z: -0.5}
                </output>
            </plugin>
        </model>
    </world>
</sdf>