<sdf version='1.10'>
  <world name='car_world'>
    <physics name='1ms' type='ode'>
      <max_step_size>0.001</max_step_size>
      <real_time_factor>1</real_time_factor>
      <real_time_update_rate>1000</real_time_update_rate>
    </physics>
    <plugin name='gz::sim::systems::Sensors' filename='gz-sim-sensors-system'>
      <render_engine>ogre2</render_engine>
    </plugin>
    <plugin name='gz::sim::systems::Physics' filename='gz-sim-physics-system'/>
    <plugin name='gz::sim::systems::UserCommands' filename='gz-sim-user-commands-system'/>
    <plugin name='gz::sim::systems::SceneBroadcaster' filename='gz-sim-scene-broadcaster-system'/>
    <plugin name='gz::sim::systems::Imu' filename='gz-sim-imu-system'/>
    <gravity>0 0 -9.8000000000000007</gravity>
    <magnetic_field>5.5644999999999998e-06 2.2875799999999999e-05 -4.2388400000000002e-05</magnetic_field>
    <atmosphere type='adiabatic'/>
    <scene>
      <ambient>0.400000006 0.400000006 0.400000006 1</ambient>
      <background>0.699999988 0.699999988 0.699999988 1</background>
      <shadows>true</shadows>
    </scene>
    <model name='ground_plane'>
      <static>true</static>
      <link name='link'>
        <collision name='collision'>
          <geometry>
            <plane>
              <normal>0 0 1</normal>
              <size>100 100</size>
            </plane>
          </geometry>
          <surface>
            <friction>
              <ode/>
            </friction>
            <bounce/>
            <contact/>
          </surface>
        </collision>
        <visual name='visual'>
          <geometry>
            <plane>
              <normal>0 0 1</normal>
              <size>100 100</size>
            </plane>
          </geometry>
          <material>
            <ambient>0.800000012 0.800000012 0.800000012 1</ambient>
            <diffuse>0.800000012 0.800000012 0.800000012 1</diffuse>
            <specular>0.800000012 0.800000012 0.800000012 1</specular>
          </material>
        </visual>
        <pose>0 0 0 0 0 0</pose>
        <inertial>
          <pose>0 0 0 0 0 0</pose>
          <mass>1</mass>
          <inertia>
            <ixx>1</ixx>
            <ixy>0</ixy>
            <ixz>0</ixz>
            <iyy>1</iyy>
            <iyz>0</iyz>
            <izz>1</izz>
          </inertia>
        </inertial>
        <enable_wind>false</enable_wind>
      </link>
      <pose>0 0 0 0 0 0</pose>
      <self_collide>false</self_collide>
    </model>
    <model name='top_view_camera'>
      <static>true</static>
      <pose>0 0 8 3.1415926535897931 1.5707926536057681 3.1415926535897931</pose>
      <link name='camera_link'>
        <sensor name='rgb_camera' type='camera'>
          <pose>0 0 0 0 0 0</pose>
          <topic>/camera/image_raw</topic>
          <update_rate>30</update_rate>
          <enable_metrics>false</enable_metrics>
          <camera name='__default__'>
            <pose>0 0 0 0 0 0</pose>
            <horizontal_fov>1.5708</horizontal_fov>
            <image>
              <width>640</width>
              <height>480</height>
              <format>RGB_INT8</format>
              <anti_aliasing>4</anti_aliasing>
            </image>
            <camera_info_topic>__default__</camera_info_topic>
            <trigger_topic></trigger_topic>
            <triggered>false</triggered>
            <clip>
              <near>0.10000000000000001</near>
              <far>15</far>
            </clip>
            <save enabled='false'>
              <path>__default__</path>
            </save>
            <visibility_mask>4294967295</visibility_mask>
            <noise>
              <type>none</type>
              <mean>0</mean>
              <stddev>0</stddev>
            </noise>
            <distortion>
              <k1>0</k1>
              <k2>0</k2>
              <k3>0</k3>
              <p1>0</p1>
              <p2>0</p2>
              <center>0.5 0.5</center>
            </distortion>
            <lens>
              <type>stereographic</type>
              <scale_to_hfov>true</scale_to_hfov>
              <cutoff_angle>1.5707963267948966</cutoff_angle>
              <env_texture_size>256</env_texture_size>
            </lens>
            <optical_frame_id></optical_frame_id>
          </camera>
        </sensor>
        <pose>0 0 0 0 0 0</pose>
        <inertial>
          <pose>0 0 0 0 0 0</pose>
          <mass>1</mass>
          <inertia>
            <ixx>1</ixx>
            <ixy>0</ixy>
            <ixz>0</ixz>
            <iyy>1</iyy>
            <iyz>0</iyz>
            <izz>1</izz>
          </inertia>
        </inertial>
        <enable_wind>false</enable_wind>
      </link>
      <self_collide>false</self_collide>
    </model>
    <model name='target'>
      <pose>3.5 2 0.20000000000000001 0 0 0</pose>
      <link name='target_link'>
        <collision name='collision'>
          <geometry>
            <sphere>
              <radius>0.20000000000000001</radius>
            </sphere>
          </geometry>
          <surface>
            <friction>
              <ode/>
            </friction>
            <bounce/>
            <contact/>
          </surface>
        </collision>
        <visual name='visual'>
          <geometry>
            <sphere>
              <radius>0.20000000000000001</radius>
            </sphere>
          </geometry>
          <material>
            <ambient>1 0 0 1</ambient>
            <diffuse>1 0 0 1</diffuse>
            <specular>1 0 0 1</specular>
            <emissive>0.200000003 0 0 1</emissive>
          </material>
        </visual>
        <pose>0 0 0 0 0 0</pose>
        <inertial>
          <pose>0 0 0 0 0 0</pose>
          <mass>1</mass>
          <inertia>
            <ixx>1</ixx>
            <ixy>0</ixy>
            <ixz>0</ixz>
            <iyy>1</iyy>
            <iyz>0</iyz>
            <izz>1</izz>
          </inertia>
        </inertial>
        <enable_wind>false</enable_wind>
      </link>
      <static>false</static>
      <self_collide>false</self_collide>
    </model>
    <model name='labyrinth'>
      <static>true</static>
      <pose>0 0 0 0 0 0</pose>
      <link name='labyrinth_link'>
        <collision name='wall1_collision'>
          <pose>-7.5 -3.5 0.5 0 0 0</pose>
          <geometry>
            <box>
              <size>0.20000000000000001 3.5 1</size>
            </box>
          </geometry>
          <surface>
            <friction>
              <ode/>
            </friction>
            <bounce/>
            <contact/>
          </surface>
        </collision>
        <visual name='wall1_visual'>
          <pose>-7.5 -3.5 0.5 0 0 0</pose>
          <geometry>
            <box>
              <size>0.20000000000000001 3.5 1</size>
            </box>
          </geometry>
          <material>
            <ambient>0 1 0 1</ambient>
            <diffuse>0 1 0 1</diffuse>
          </material>
        </visual>

        <collision name='wall1extra_collision'>
          <pose>-7.5 3.5 0.5 0 0 0</pose>
          <geometry>
            <box>
              <size>0.20000000000000001 3.5 1</size>
            </box>
          </geometry>
          <surface>
            <friction>
              <ode/>
            </friction>
            <bounce/>
            <contact/>
          </surface>
        </collision>
        <visual name='wall1extra_visual'>
          <pose>-7.5 3.5 0.5 0 0 0</pose>
          <geometry>
            <box>
              <size>0.20000000000000001 3.5 1</size>
            </box>
          </geometry>
          <material>
            <ambient>0 1 0 1</ambient>
            <diffuse>0 1 0 1</diffuse>
          </material>
        </visual>

        <collision name='wall1extra2_collision'>
          <pose>-8.5 0 0.5 0 0 0</pose>
          <geometry>
            <box>
              <size>0.20000000000000001 4 1</size>
            </box>
          </geometry>
          <surface>
            <friction>
              <ode/>
            </friction>
            <bounce/>
            <contact/>
          </surface>
        </collision>
        <visual name='wall1extra2_visual'>
          <pose>-8.5 0 0.5 0 0 0</pose>
          <geometry>
            <box>
              <size>0.20000000000000001 4 1</size>
            </box>
          </geometry>
          <material>
            <ambient>0 1 0 1</ambient>
            <diffuse>0 1 0 1</diffuse>
          </material>
        </visual>

        <collision name='wall1extra3_collision'>
          <pose>8.5 0 0.5 0 0 0</pose>
          <geometry>
            <box>
              <size>0.20000000000000001 4 1</size>
            </box>
          </geometry>
          <surface>
            <friction>
              <ode/>
            </friction>
            <bounce/>
            <contact/>
          </surface>
        </collision>
        <visual name='wall1extra3_visual'>
          <pose>8.5 0 0.5 0 0 0</pose>
          <geometry>
            <box>
              <size>0.20000000000000001 4 1</size>
            </box>
          </geometry>
          <material>
            <ambient>0 1 0 1</ambient>
            <diffuse>0 1 0 1</diffuse>
          </material>
        </visual>

        <collision name='wall2_collision'>
          <pose>7.5 3.5 0.5 0 0 0</pose>
          <geometry>
            <box>
              <size>0.20000000000000001 3.5 1</size>
            </box>
          </geometry>
          <surface>
            <friction>
              <ode/>
            </friction>
            <bounce/>
            <contact/>
          </surface>
        </collision>
        <visual name='wall2_visual'>
          <pose>7.5 3.5 0.5 0 0 0</pose>
          <geometry>
            <box>
              <size>0.20000000000000001 3.5 1</size>
            </box>
          </geometry>
          <material>
            <ambient>0 1 0 1</ambient>
            <diffuse>0 1 0 1</diffuse>
          </material>
        </visual>
        <collision name='wall2extra_collision'>
          <pose>7.5 -3.5 0.5 0 0 0</pose>
          <geometry>
            <box>
              <size>0.20000000000000001 3.5 1</size>
            </box>
          </geometry>
          <surface>
            <friction>
              <ode/>
            </friction>
            <bounce/>
            <contact/>
          </surface>
        </collision>
        <visual name='wall2extra_visual'>
          <pose>7.5 -3.5 0.5 0 0 0</pose>
          <geometry>
            <box>
              <size>0.20000000000000001 3.5 1</size>
            </box>
          </geometry>
          <material>
            <ambient>0 1 0 1</ambient>
            <diffuse>0 1 0 1</diffuse>
          </material>
        </visual>
        <collision name='wall3_collision'>
          <pose>0 5 0.5 0 0 1.5708</pose>
          <geometry>
            <box>
              <size>0.20000000000000001 15 1</size>
            </box>
          </geometry>
          <surface>
            <friction>
              <ode/>
            </friction>
            <bounce/>
            <contact/>
          </surface>
        </collision>
        <visual name='wall3_visual'>
          <pose>0 5 0.5 0 0 1.5708</pose>
          <geometry>
            <box>
              <size>0.20000000000000001 15 1</size>
            </box>
          </geometry>
          <material>
            <ambient>0 1 0 1</ambient>
            <diffuse>0 1 0 1</diffuse>
          </material>
        </visual>
        <collision name='wall4a_collision'>
          <pose>-2 -5 0.5 0 0 1.5708</pose>
          <geometry>
            <box>
              <size>0.20000000000000001 11 1</size>
            </box>
          </geometry>
          <surface>
            <friction>
              <ode/>
            </friction>
            <bounce/>
            <contact/>
          </surface>
        </collision>
        <visual name='wall4a_visual'>
          <pose>-2 -5 0.5 0 0 1.5708</pose>
          <geometry>
            <box>
              <size>0.20000000000000001 11 1</size>
            </box>
          </geometry>
          <material>
            <ambient>0 1 0 1</ambient>
            <diffuse>0 1 0 1</diffuse>
          </material>
        </visual>

        <collision name='wall4a2_collision'>
          <pose>8 -2 0.5 0 0 1.5708</pose>
          <geometry>
            <box>
              <size>0.20000000000000001 1.5 1</size>
            </box>
          </geometry>
          <surface>
            <friction>
              <ode/>
            </friction>
            <bounce/>
            <contact/>
          </surface>
        </collision>
        <visual name='wall4a2_visual'>
          <pose>8 -2 0.5 0 0 1.5708</pose>
          <geometry>
            <box>
              <size>0.20000000000000001 1.5 1</size>
            </box>
          </geometry>
          <material>
            <ambient>0 1 0 1</ambient>
            <diffuse>0 1 0 1</diffuse>
          </material>
        </visual>

        <collision name='wall4a2b_collision'>
          <pose>8 2 0.5 0 0 1.5708</pose>
          <geometry>
            <box>
              <size>0.20000000000000001 1.5 1</size>
            </box>
          </geometry>
          <surface>
            <friction>
              <ode/>
            </friction>
            <bounce/>
            <contact/>
          </surface>
        </collision>
        <visual name='wall4a2b_visual'>
          <pose>8 2 0.5 0 0 1.5708</pose>
          <geometry>
            <box>
              <size>0.20000000000000001 1.5 1</size>
            </box>
          </geometry>
          <material>
            <ambient>0 1 0 1</ambient>
            <diffuse>0 1 0 1</diffuse>
          </material>
        </visual>

        <collision name='wall4a3_collision'>
          <pose>-8 -2 0.5 0 0 1.5708</pose>
          <geometry>
            <box>
              <size>0.20000000000000001 1.5 1</size>
            </box>
          </geometry>
          <surface>
            <friction>
              <ode/>
            </friction>
            <bounce/>
            <contact/>
          </surface>
        </collision>
        <visual name='wall4a3_visual'>
          <pose>-8 -2 0.5 0 0 1.5708</pose>
          <geometry>
            <box>
              <size>0.20000000000000001 1.5 1</size>
            </box>
          </geometry>
          <material>
            <ambient>0 1 0 1</ambient>
            <diffuse>0 1 0 1</diffuse>
          </material>
        </visual>

        <collision name='wall4a3b_collision'>
          <pose>-8 2 0.5 0 0 1.5708</pose>
          <geometry>
            <box>
              <size>0.20000000000000001 1.5 1</size>
            </box>
          </geometry>
          <surface>
            <friction>
              <ode/>
            </friction>
            <bounce/>
            <contact/>
          </surface>
        </collision>
        <visual name='wall4a3b_visual'>
          <pose>-8 2 0.5 0 0 1.5708</pose>
          <geometry>
            <box>
              <size>0.20000000000000001 1.5 1</size>
            </box>
          </geometry>
          <material>
            <ambient>0 1 0 1</ambient>
            <diffuse>0 1 0 1</diffuse>
          </material>
        </visual>

        <collision name='wall4b_collision'>
          <pose>3 -5 0.5 0 0 1.5708</pose>
          <geometry>
            <box>
              <size>0.20000000000000001 9 1</size>
            </box>
          </geometry>
          <surface>
            <friction>
              <ode/>
            </friction>
            <bounce/>
            <contact/>
          </surface>
        </collision>
        <visual name='wall4b_visual'>
          <pose>3 -5 0.5 0 0 1.5708</pose>
          <geometry>
            <box>
              <size>0.20000000000000001 9 1</size>
            </box>
          </geometry>
          <material>
            <ambient>0 1 0 1</ambient>
            <diffuse>0 1 0 1    </diffuse>
          </material>
        </visual>
        <pose>0 0 0 0 0 0</pose>
        <inertial>
          <pose>0 0 0 0 0 0</pose>
          <mass>1</mass>
          <inertia>
            <ixx>1</ixx>
            <ixy>0</ixy>
            <ixz>0</ixz>
            <iyy>1</iyy>
            <iyz>0</iyz>
            <izz>1</izz>
          </inertia>
        </inertial>
        <enable_wind>false</enable_wind>
      </link>
      <self_collide>false</self_collide>
    </model>
    <model name='vehicle_blue' canonical_link='chassis'>
      <pose>-5 0 0 0 0 0</pose>
      <link name='chassis'>
        <pose>-1 -1 0.33500000000000002 0 0 0</pose>
        <inertial>
          <mass>1.14395</mass>
          <inertia>
            <ixx>0.095328999999999997</ixx>
            <ixy>0</ixy>
            <ixz>0</ixz>
            <iyy>0.38131700000000002</iyy>
            <iyz>0</iyz>
            <izz>0.47664600000000001</izz>
          </inertia>
          <pose>0 0 0 0 0 0</pose>
        </inertial>
        <visual name='visual'>
          <pose>0.69999999999999996 0.69999999999999996 -0.26000000000000001 1.5707 -5.5511151231257827e-17 -1.5707</pose>
          <geometry>
            <mesh>
              <uri>file:///home/aldon/ros2_ws/src/my_robot/MySDF/ROBOT.STL</uri>
              <scale>0.01 0.01 0.01</scale>
            </mesh>
          </geometry>
          <material>
            <ambient>0 0 1 1</ambient>
            <diffuse>0 0 1 1</diffuse>
            <specular>0 0 1 1</specular>
          </material>
        </visual>
        <collision name='collision'>
          <pose>0.69999999999999996 0.69999999999999996 -0.26000000000000001 1.5707 -5.5511151231257827e-17 -1.5707</pose>
          <geometry>
            <mesh>
              <uri>file:///home/aldon/ros2_ws/src/my_robot/MySDF/ROBOT.STL</uri>
              <scale>0.01 0.01 0.01</scale>
            </mesh>
          </geometry>
        </collision>
        <sensor name='imu_sensor' type='imu'>
          <pose>0 0 0 0 0 0</pose>
          <topic>/imu</topic>
          <update_rate>100</update_rate>
          <enable_metrics>false</enable_metrics>
          <imu>
            <orientation_reference_frame>
              <localization>CUSTOM</localization>
              <custom_rpy>0 0 0</custom_rpy>
              <grav_dir_x>1 0 0</grav_dir_x>
            </orientation_reference_frame>
            <angular_velocity>
              <x>
                <noise type='none'>
                  <mean>0</mean>
                  <stddev>0</stddev>
                  <bias_mean>0</bias_mean>
                  <bias_stddev>0</bias_stddev>
                  <dynamic_bias_stddev>0</dynamic_bias_stddev>
                  <dynamic_bias_correlation_time>0</dynamic_bias_correlation_time>
                  <precision>0</precision>
                </noise>
              </x>
              <y>
                <noise type='none'>
                  <mean>0</mean>
                  <stddev>0</stddev>
                  <bias_mean>0</bias_mean>
                  <bias_stddev>0</bias_stddev>
                  <dynamic_bias_stddev>0</dynamic_bias_stddev>
                  <dynamic_bias_correlation_time>0</dynamic_bias_correlation_time>
                  <precision>0</precision>
                </noise>
              </y>
              <z>
                <noise type='none'>
                  <mean>0</mean>
                  <stddev>0</stddev>
                  <bias_mean>0</bias_mean>
                  <bias_stddev>0</bias_stddev>
                  <dynamic_bias_stddev>0</dynamic_bias_stddev>
                  <dynamic_bias_correlation_time>0</dynamic_bias_correlation_time>
                  <precision>0</precision>
                </noise>
              </z>
            </angular_velocity>
            <linear_acceleration>
              <x>
                <noise type='none'>
                  <mean>0</mean>
                  <stddev>0</stddev>
                  <bias_mean>0</bias_mean>
                  <bias_stddev>0</bias_stddev>
                  <dynamic_bias_stddev>0</dynamic_bias_stddev>
                  <dynamic_bias_correlation_time>0</dynamic_bias_correlation_time>
                  <precision>0</precision>
                </noise>
              </x>
              <y>
                <noise type='none'>
                  <mean>0</mean>
                  <stddev>0</stddev>
                  <bias_mean>0</bias_mean>
                  <bias_stddev>0</bias_stddev>
                  <dynamic_bias_stddev>0</dynamic_bias_stddev>
                  <dynamic_bias_correlation_time>0</dynamic_bias_correlation_time>
                  <precision>0</precision>
                </noise>
              </y>
              <z>
                <noise type='none'>
                  <mean>0</mean>
                  <stddev>0</stddev>
                  <bias_mean>0</bias_mean>
                  <bias_stddev>0</bias_stddev>
                  <dynamic_bias_stddev>0</dynamic_bias_stddev>
                  <dynamic_bias_correlation_time>0</dynamic_bias_correlation_time>
                  <precision>0</precision>
                </noise>
              </z>
            </linear_acceleration>
            <enable_orientation>true</enable_orientation>
          </imu>
        </sensor>
        <enable_wind>false</enable_wind>
      </link>
      <link name='left_wheel'>
        <pose>-1.4000000000000004 -0.10499999999999998 0.33500000000000002 1.5706999999999995 0 0</pose>
        <inertial>
          <mass>1</mass>
          <inertia>
            <ixx>0.043333000000000003</ixx>
            <ixy>0</ixy>
            <ixz>0</ixz>
            <iyy>0.043333000000000003</iyy>
            <iyz>0</iyz>
            <izz>0.080000000000000002</izz>
          </inertia>
          <pose>0 0 0 0 0 0</pose>
        </inertial>
        <visual name='visual'>
          <geometry>
            <cylinder>
              <radius>0.33500000000000002</radius>
              <length>0.25</length>
            </cylinder>
          </geometry>
          <material>
            <ambient>0 0 0 1</ambient>
            <diffuse>0 0 0 1</diffuse>
            <specular>0 0 0 1</specular>
          </material>
        </visual>
        <collision name='collision'>
          <geometry>
            <cylinder>
              <radius>0.33500000000000002</radius>
              <length>0.25</length>
            </cylinder>
          </geometry>
          <surface>
            <friction>
              <ode/>
            </friction>
            <bounce/>
            <contact/>
          </surface>
        </collision>
        <enable_wind>false</enable_wind>
      </link>
      <link name='right_wheel'>
        <pose>-1.4000000000000004 -1.895 0.33500000000000002 1.5706999999999995 0 0</pose>
        <inertial>
          <mass>1</mass>
          <inertia>
            <ixx>0.043333000000000003</ixx>
            <ixy>0</ixy>
            <ixz>0</ixz>
            <iyy>0.043333000000000003</iyy>
            <iyz>0</iyz>
            <izz>0.080000000000000002</izz>
          </inertia>
          <pose>0 0 0 0 0 0</pose>
        </inertial>
        <visual name='visual'>
          <geometry>
            <cylinder>
              <radius>0.33500000000000002</radius>
              <length>0.25</length>
            </cylinder>
          </geometry>
          <material>
            <ambient>0 0 0 1</ambient>
            <diffuse>0 0 0 1</diffuse>
            <specular>0 0 0 1</specular>
          </material>
        </visual>
        <collision name='collision'>
          <geometry>
            <cylinder>
              <radius>0.33500000000000002</radius>
              <length>0.25</length>
            </cylinder>
          </geometry>
          <surface>
            <friction>
              <ode/>
            </friction>
            <bounce/>
            <contact/>
          </surface>
        </collision>
        <enable_wind>false</enable_wind>
      </link>
      <frame name='caster_frame'>
        <pose relative_to='chassis'>0.59999999999999998 0 -0.28999999999999998 0 0 0</pose>
      </frame>
      <link name='caster'>
        <pose>-0.40000000000000036 -1 0.04500000000000004 0 0 0</pose>
        <inertial>
          <mass>1</mass>
          <inertia>
            <ixx>0.016</ixx>
            <ixy>0</ixy>
            <ixz>0</ixz>
            <iyy>0.016</iyy>
            <iyz>0</iyz>
            <izz>0.016</izz>
          </inertia>
          <pose>0 0 0 0 0 0</pose>
        </inertial>
        <visual name='visual'>
          <geometry>
            <sphere>
              <radius>0.044999999999999998</radius>
            </sphere>
          </geometry>
          <material>
            <ambient>0 1 0 1</ambient>
            <diffuse>0 1 0 1</diffuse>
            <specular>0 1 0 1</specular>
          </material>
        </visual>
        <collision name='collision'>
          <geometry>
            <sphere>
              <radius>0.20000000000000001</radius>
            </sphere>
          </geometry>
          <surface>
            <friction>
              <ode/>
            </friction>
            <bounce/>
            <contact/>
          </surface>
        </collision>
        <enable_wind>false</enable_wind>
      </link>
      <joint name='left_wheel_joint' type='revolute'>
        <pose>0 0 -6.9388939039072284e-17 0 0 0</pose>
        <parent>chassis</parent>
        <child>left_wheel</child>
        <axis>
          <xyz>0 9.6326794747692026e-05 -0.99999999536057438</xyz>
          <limit>
            <lower>-1.7976900000000001e+308</lower>
            <upper>1.7976900000000001e+308</upper>
            <effort>inf</effort>
            <velocity>inf</velocity>
            <stiffness>100000000</stiffness>
            <dissipation>1</dissipation>
          </limit>
          <dynamics>
            <spring_reference>0</spring_reference>
            <spring_stiffness>0</spring_stiffness>
            <damping>0</damping>
            <friction>0</friction>
          </dynamics>
        </axis>
      </joint>
      <joint name='right_wheel_joint' type='revolute'>
        <pose>0 4.4408920985006262e-16 6.6613381477509392e-16 0 0 0</pose>
        <parent>chassis</parent>
        <child>right_wheel</child>
        <axis>
          <xyz>0 9.6326794747692026e-05 -0.99999999536057438</xyz>
          <limit>
            <lower>-1.7976900000000001e+308</lower>
            <upper>1.7976900000000001e+308</upper>
            <effort>inf</effort>
            <velocity>inf</velocity>
            <stiffness>100000000</stiffness>
            <dissipation>1</dissipation>
          </limit>
          <dynamics>
            <spring_reference>0</spring_reference>
            <spring_stiffness>0</spring_stiffness>
            <damping>0</damping>
            <friction>0</friction>
          </dynamics>
        </axis>
      </joint>
      <joint name='caster_wheel' type='ball'>
        <parent>chassis</parent>
        <child>caster</child>
        <pose>0 0 0 0 0 0</pose>
      </joint>
      <plugin name='gz::sim::systems::DiffDrive' filename='gz-sim-diff-drive-system'>
        <left_joint>left_wheel_joint</left_joint>
        <right_joint>right_wheel_joint</right_joint>
        <wheel_separation>1.54</wheel_separation>
        <wheel_radius>0.35</wheel_radius>
        <odom_publish_frequency>1</odom_publish_frequency>
        <topic>/cmd_vel</topic>
      </plugin>
      <plugin name='gz::sim::systems::TriggeredPublisher' filename='gz-sim-triggered-publisher-system'>
        <input type='gz.msgs.Int32' topic='/keyboard/keypress'>
          <match field='data'>16777237</match>
        </input>
        <output type='gz.msgs.Twist' topic='/cmd_vel'>linear: {x: -0.5}, angular: {z: 0.0}</output>
      </plugin>
      <plugin name='gz::sim::systems::TriggeredPublisher' filename='gz-sim-triggered-publisher-system'>
        <input type='gz.msgs.Int32' topic='/keyboard/keypress'>
          <match field='data'>16777234</match>
        </input>
        <output type='gz.msgs.Twist' topic='/cmd_vel'>linear: {x: 0.0}, angular: {z: 0.5}</output>
      </plugin>
      <plugin name='gz::sim::systems::TriggeredPublisher' filename='gz-sim-triggered-publisher-system'>
        <input type='gz.msgs.Int32' topic='/keyboard/keypress'>
          <match field='data'>16777235</match>
        </input>
        <output type='gz.msgs.Twist' topic='/cmd_vel'>linear: {x: 0.5}, angular: {z: 0.0}</output>
      </plugin>
      <plugin name='gz::sim::systems::TriggeredPublisher' filename='gz-sim-triggered-publisher-system'>
        <input type='gz.msgs.Int32' topic='/keyboard/keypress'>
          <match field='data'>16777236</match>
        </input>
        <output type='gz.msgs.Twist' topic='/cmd_vel'>linear: {x: 0.0}, angular: {z: -0.5}</output>
      </plugin>
      <static>false</static>
      <self_collide>false</self_collide>
    </model>
    <light name='sun' type='directional'>
      <pose>0 0 10 0 0 0</pose>
      <cast_shadows>true</cast_shadows>
      <intensity>1</intensity>
      <direction>0 0.10000000000000001 -0.90000000000000002</direction>
      <diffuse>0.800000012 0.800000012 0.800000012 1</diffuse>
      <specular>0.200000003 0.200000003 0.200000003 1</specular>
      <attenuation>
        <range>1000</range>
        <linear>0.01</linear>
        <constant>0.90000000000000002</constant>
        <quadratic>0.001</quadratic>
      </attenuation>
      <spot>
        <inner_angle>0</inner_angle>
        <outer_angle>0</outer_angle>
        <falloff>0</falloff>
      </spot>
    </light>
  </world>
</sdf>
